Workbook

Sheet Gantt 15 semanas
B2: CRONOGRAMA DE TESIS | M2: Gantt de edición manual
B4: Desarrollo de un manipulador móvil asistente doméstico basado en aprendizaje robótico y comprensión semántica para personas con movilidad reducida.
B5: Semana 4: del 14 al 20 de septiembre de 2026. | F5: Avance global | H5: =IF(COUNT('Plan de trabajo'!J12:J65)=54,SUMPRODUCT('Plan de trabajo'!J12:J65,'Plan de trabajo'!E12:E65)/SUM('Plan de trabajo'!E12:E65),"") | I5: Porcentaje vacío: sin reporte | M5: Calendario: 24/08/2026 al 04/12/2026. 15 semanas. | T5: Semanas 1 a 3: programación histórica por confirmar.
B6: Mueve bloques con Cortar y Pegar (Ctrl+X / Ctrl+V). | E6: Rojo y azul: rellenos manuales editables. | I6: Sin ruta crítica automática. | M6: Para quitar un bloque: Inicio > Borrar > Borrar formatos, o Color de relleno > Sin relleno.
B7: Inicio y fin son editables. Fechas y bloques se ajustan por separado. | M7: Para añadir un bloque: copia uno del color deseado o aplica Color de relleno.
B8: ID | C8: EDT | D8: Actividad | E8: Porcentaje | F8: Inicio | G8: Fin | H8: Duración (días) | I8: Crítica (manual) | J8: Notas | K8: Estado | M8: AGOSTO | O8: SEPTIEMBRE | S8: OCTUBRE | W8: NOVIEMBRE | AA8: NOV. / DIC.
M9: 1 | N9: 2 | O9: 3 | P9: 4 | Q9: 5 | R9: 6 | S9: 7 | T9: 8 | U9: 9 | V9: 10 | W9: 11 | X9: 12 | Y9: 13 | Z9: 14 | AA9: 15
M10: 46258 | N10: 46265 | O10: 46272 | P10: 46279 | Q10: 46286 | R10: 46293 | S10: 46300 | T10: 46307 | U10: 46314 | V10: 46321 | W10: 46328 | X10: 46335 | Y10: 46342 | Z10: 46349 | AA10: 46356
M11: 46264 | N11: 46271 | O11: 46278 | P11: 46285 | Q11: 46292 | R11: 46299 | S11: 46306 | T11: 46313 | U11: 46320 | V11: 46327 | W11: 46334 | X11: 46341 | Y11: 46348 | Z11: 46355 | AA11: 46360
B13: 1. Plataforma mecánica ensamblada | E13: =IF(COUNT(E14:E22)=9,SUMPRODUCT(E14:E22,'Plan de trabajo'!E12:E20)/SUM('Plan de trabajo'!E12:E20),"") | F13: =IF(COUNT(F14:F22)=0,"",MIN(F14:F22)) -> 46258 | G13: =IF(COUNT(G14:G22)=0,"",MAX(G14:G22)) -> 46306 | H13: =NETWORKDAYS(F13,G13) -> 35
B14: M01 | C14: 1.1 | D14: Inventariar componentes, materiales y disponibilidad | E14: 1 | F14: 46258 | G14: 46264 | H14: =IF(COUNT(F14:G14)<2,"",NETWORKDAYS(F14,G14)) -> 5 | I14: Sí | K14: =IF(COUNT(E14)=0,"Sin reporte",IF(E14=1,"Completada",IF(G14<46279,"Revisar retraso",IF(E14>0,"En curso","Sin iniciar")))) -> Completada
B15: M02 | C15: 1.1 | D15: Revisar STL, tolerancias y preparar archivos | E15: 1 | F15: 46265 | G15: 46271 | H15: =IF(COUNT(F15:G15)<2,"",NETWORKDAYS(F15,G15)) -> 5 | I15: Sí | K15: =IF(COUNT(E15)=0,"Sin reporte",IF(E15=1,"Completada",IF(G15<46279,"Revisar retraso",IF(E15>0,"En curso","Sin iniciar")))) -> Completada
B16: M03 | C16: 1.1 | D16: Imprimir y verificar las piezas de la base | E16: 1 | F16: 46272 | G16: 46285 | H16: =IF(COUNT(F16:G16)<2,"",NETWORKDAYS(F16,G16)) -> 10 | I16: Sí | K16: =IF(COUNT(E16)=0,"Sin reporte",IF(E16=1,"Completada",IF(G16<46279,"Revisar retraso",IF(E16>0,"En curso","Sin iniciar")))) -> Completada
B17: M04 | C17: 1.2 | D17: Imprimir brazos, pinzas y estructura de elevación | E17: 0.5 | F17: 46279 | G17: 46292 | H17: =IF(COUNT(F17:G17)<2,"",NETWORKDAYS(F17,G17)) -> 10 | I17: Sí | K17: =IF(COUNT(E17)=0,"Sin reporte",IF(E17=1,"Completada",IF(G17<46279,"Revisar retraso",IF(E17>0,"En curso","Sin iniciar")))) -> En curso
B18: M05 | C18: 1.1 | D18: Ensamblar chasis, ruedas y transmisión | F18: 46286 | G18: 46299 | H18: =IF(COUNT(F18:G18)<2,"",NETWORKDAYS(F18,G18)) -> 10 | I18: No | K18: =IF(COUNT(E18)=0,"Sin reporte",IF(E18=1,"Completada",IF(G18<46279,"Revisar retraso",IF(E18>0,"En curso","Sin iniciar")))) -> Sin reporte
B19: M06 | C19: 1.2 | D19: Ensamblar ambos brazos y las pinzas | F19: 46293 | G19: 46306 | H19: =IF(COUNT(F19:G19)<2,"",NETWORKDAYS(F19,G19)) -> 10 | I19: Sí | K19: =IF(COUNT(E19)=0,"Sin reporte",IF(E19=1,"Completada",IF(G19<46279,"Revisar retraso",IF(E19>0,"En curso","Sin iniciar")))) -> Sin reporte
B20: M07 | C20: 1.2 | D20: Ensamblar y ajustar el mecanismo de elevación | F20: 46300 | G20: 46306 | H20: =IF(COUNT(F20:G20)<2,"",NETWORKDAYS(F20,G20)) -> 5 | I20: Sí | K20: =IF(COUNT(E20)=0,"Sin reporte",IF(E20=1,"Completada",IF(G20<46279,"Revisar retraso",IF(E20>0,"En curso","Sin iniciar")))) -> Sin reporte
B21: M08 | C21: 1.3 | D21: Adaptar soportes de sensores, batería y cómputo | F21: 46300 | G21: 46306 | H21: =IF(COUNT(F21:G21)<2,"",NETWORKDAYS(F21,G21)) -> 5 | I21: No | K21: =IF(COUNT(E21)=0,"Sin reporte",IF(E21=1,"Completada",IF(G21<46279,"Revisar retraso",IF(E21>0,"En curso","Sin iniciar")))) -> Sin reporte
B22: M09 | C22: 1.3 | D22: Imprimir y montar soportes; sujetar el cableado | F22: 46300 | G22: 46306 | H22: =IF(COUNT(F22:G22)<2,"",NETWORKDAYS(F22,G22)) -> 5 | I22: No | K22: =IF(COUNT(E22)=0,"Sin reporte",IF(E22=1,"Completada",IF(G22<46279,"Revisar retraso",IF(E22>0,"En curso","Sin iniciar")))) -> Sin reporte
B23: 2. Sistema eléctrico, electrónico y de control básico | E23: =IF(COUNT(E24:E29)=6,SUMPRODUCT(E24:E29,'Plan de trabajo'!E21:E26)/SUM('Plan de trabajo'!E21:E26),"") | F23: =IF(COUNT(F24:F29)=0,"",MIN(F24:F29)) -> 46265 | G23: =IF(COUNT(G24:G29)=0,"",MAX(G24:G29)) -> 46306 | H23: =NETWORKDAYS(F23,G23) -> 30
B24: E01 | C24: 2.1 | D24: Definir distribución eléctrica | E24: 1 | F24: 46265 | G24: 46271 | H24: =IF(COUNT(F24:G24)<2,"",NETWORKDAYS(F24,G24)) -> 5 | I24: No | K24: =IF(COUNT(E24)=0,"Sin reporte",IF(E24=1,"Completada",IF(G24<46279,"Revisar retraso",IF(E24>0,"En curso","Sin iniciar")))) -> Completada
B25: E02 | C25: 2.1 | D25: Integrar batería, regulación y cableado | F25: 46293 | G25: 46299 | H25: =IF(COUNT(F25:G25)<2,"",NETWORKDAYS(F25,G25)) -> 5 | I25: Sí | K25: =IF(COUNT(E25)=0,"Sin reporte",IF(E25=1,"Completada",IF(G25<46279,"Revisar retraso",IF(E25>0,"En curso","Sin iniciar")))) -> Sin reporte
B26: E03 | C26: 2.2 | D26: Configurar motores, referencias y límites | F26: 46300 | G26: 46306 | H26: =IF(COUNT(F26:G26)<2,"",NETWORKDAYS(F26,G26)) -> 5 | I26: Sí | K26: =IF(COUNT(E26)=0,"Sin reporte",IF(E26=1,"Completada",IF(G26<46279,"Revisar retraso",IF(E26>0,"En curso","Sin iniciar")))) -> Sin reporte
B27: E04 | C27: 2.2 | D27: Verificar parada y movimientos manuales | F27: 46300 | G27: 46306 | H27: =IF(COUNT(F27:G27)<2,"",NETWORKDAYS(F27,G27)) -> 5 | I27: Sí | K27: =IF(COUNT(E27)=0,"Sin reporte",IF(E27=1,"Completada",IF(G27<46279,"Revisar retraso",IF(E27>0,"En curso","Sin iniciar")))) -> Sin reporte
B28: E05 | C28: 2.3 | D28: Conectar LiDAR, cámaras, computador y red | F28: 46300 | G28: 46306 | H28: =IF(COUNT(F28:G28)<2,"",NETWORKDAYS(F28,G28)) -> 5 | I28: Sí | K28: =IF(COUNT(E28)=0,"Sin reporte",IF(E28=1,"Completada",IF(G28<46279,"Revisar retraso",IF(E28>0,"En curso","Sin iniciar")))) -> Sin reporte
B29: E06 | C29: 2.3 | D29: Calibrar sensores y comprobar sincronización | F29: 46300 | G29: 46306 | H29: =IF(COUNT(F29:G29)<2,"",NETWORKDAYS(F29,G29)) -> 5 | I29: Sí | K29: =IF(COUNT(E29)=0,"Sin reporte",IF(E29=1,"Completada",IF(G29<46279,"Revisar retraso",IF(E29>0,"En curso","Sin iniciar")))) -> Sin reporte
B30: 3. Sistema de mapeo y navegación | E30: =IF(COUNT(E31:E37)=5,SUMPRODUCT(E31:E37,'Plan de trabajo'!E27:E31)/SUM('Plan de trabajo'!E27:E31),"") | F30: =IF(COUNT(F31:F37)=0,"",MIN(F31:F37)) -> 46265 | G30: =IF(COUNT(G31:G37)=0,"",MAX(G31:G37)) -> 46334 | H30: =NETWORKDAYS(F30,G30) -> 50
B31: N01 | C31: 3.1 | D31: Preparar middleware, entorno y controladores base | E31: 1 | F31: 46265 | G31: 46278 | H31: =IF(COUNT(F31:G31)<2,"",NETWORKDAYS(F31,G31)) -> 10 | I31: No | K31: =IF(COUNT(E31)=0,"Sin reporte",IF(E31=1,"Completada",IF(G31<46279,"Revisar retraso",IF(E31>0,"En curso","Sin iniciar")))) -> Completada
B32: N02 | C32: 46056 | D32: Integrar odometría y navegación de la base | E32: 1 | F32: 46272 | G32: 46285 | H32: =IF(COUNT(F32:G32)<2,"",NETWORKDAYS(F32,G32)) -> 10 | I32: No | K32: =IF(COUNT(E32)=0,"Sin reporte",IF(E32=1,"Completada",IF(G32<46279,"Revisar retraso",IF(E32>0,"En curso","Sin iniciar")))) -> Completada
B33: N03 | C33: 46056 | D33: Validar navegación en simulación | E33: 0.5 | F33: 46279 | G33: 46292 | H33: =IF(COUNT(F33:G33)<2,"",NETWORKDAYS(F33,G33)) -> 10 | I33: No | K33: =IF(COUNT(E33)=0,"Sin reporte",IF(E33=1,"Completada",IF(G33<46279,"Revisar retraso",IF(E33>0,"En curso","Sin iniciar")))) -> En curso
B34: N03 | C34: 3.1 | D34: Mapear la vivienda y validar relocalización | F34: 46307 | G34: 46320 | H34: =IF(COUNT(F34:G34)<2,"",NETWORKDAYS(F34,G34)) -> 10 | I34: No | K34: =IF(COUNT(E34)=0,"Sin reporte",IF(E34=1,"Completada",IF(G34<46279,"Revisar retraso",IF(E34>0,"En curso","Sin iniciar")))) -> Sin reporte
B35: N04 | C35: 3.2 | D35: Configurar habitaciones y destinos semánticos | F35: 46314 | G35: 46327 | H35: =IF(COUNT(F35:G35)<2,"",NETWORKDAYS(F35,G35)) -> 10 | I35: No | K35: =IF(COUNT(E35)=0,"Sin reporte",IF(E35=1,"Completada",IF(G35<46279,"Revisar retraso",IF(E35>0,"En curso","Sin iniciar")))) -> Sin reporte
B36: N03 | C36: 46056 | D36: Conectar la navegación con las ubicaciones recuperadas de la memoria semántica | F36: 46321 | G36: 46327 | H36: =IF(COUNT(F36:G36)<2,"",NETWORKDAYS(F36,G36)) -> 5 | I36: No | K36: =IF(COUNT(E36)=0,"Sin reporte",IF(E36=1,"Completada",IF(G36<46279,"Revisar retraso",IF(E36>0,"En curso","Sin iniciar")))) -> Sin reporte
B37: N05 | C37: 3.3 | D37: Ajustar aproximación a recogida y entrega | F37: 46328 | G37: 46334 | H37: =IF(COUNT(F37:G37)<2,"",NETWORKDAYS(F37,G37)) -> 5 | I37: Sí | K37: =IF(COUNT(E37)=0,"Sin reporte",IF(E37=1,"Completada",IF(G37<46279,"Revisar retraso",IF(E37>0,"En curso","Sin iniciar")))) -> Sin reporte
B38: N03 | C38: 46084 | D38: Validar navegación transportando objetos | F38: 46328 | G38: 46341 | H38: =IF(COUNT(F38:G38)<2,"",NETWORKDAYS(F38,G38)) -> 10 | I38: No | K38: =IF(COUNT(E38)=0,"Sin reporte",IF(E38=1,"Completada",IF(G38<46279,"Revisar retraso",IF(E38>0,"En curso","Sin iniciar")))) -> Sin reporte
B39: 4. Sistema de percepción y memoria semántica | E39: =IF(COUNT(E40:E43)=3,SUMPRODUCT(E40:E43,'Plan de trabajo'!E32:E34)/SUM('Plan de trabajo'!E32:E34),"") | F39: =IF(COUNT(F40:F43)=0,"",MIN(F40:F43)) -> 46307 | G39: =IF(COUNT(G40:G43)=0,"",MAX(G40:G43)) -> 46334 | H39: =NETWORKDAYS(F39,G39) -> 20
B40: P01 | C40: 4.1 | D40: Integrar reconocimiento y localización de objetos | F40: 46307 | G40: 46313 | H40: =IF(COUNT(F40:G40)<2,"",NETWORKDAYS(F40,G40)) -> 5 | I40: Sí | K40: =IF(COUNT(E40)=0,"Sin reporte",IF(E40=1,"Completada",IF(G40<46279,"Revisar retraso",IF(E40>0,"En curso","Sin iniciar")))) -> Sin reporte
B41: P01 | C41: 4.1 | D41: Asociar los objetos detectados con su ubicación espacial | F41: 46314 | G41: 46320 | H41: =IF(COUNT(F41:G41)<2,"",NETWORKDAYS(F41,G41)) -> 5 | I41: Sí | K41: =IF(COUNT(E41)=0,"Sin reporte",IF(E41=1,"Completada",IF(G41<46279,"Revisar retraso",IF(E41>0,"En curso","Sin iniciar")))) -> Sin reporte
B42: P02 | C42: 4.2 | D42: Configurar memoria persistente de objetos y lugares | F42: 46314 | G42: 46327 | H42: =IF(COUNT(F42:G42)<2,"",NETWORKDAYS(F42,G42)) -> 10 | I42: Sí | K42: =IF(COUNT(E42)=0,"Sin reporte",IF(E42=1,"Completada",IF(G42<46279,"Revisar retraso",IF(E42>0,"En curso","Sin iniciar")))) -> Sin reporte
B43: P03 | C43: 4.3 | D43: Probar consultas, confirmación visual y actualización | F43: 46321 | G43: 46334 | H43: =IF(COUNT(F43:G43)<2,"",NETWORKDAYS(F43,G43)) -> 10 | I43: Sí | K43: =IF(COUNT(E43)=0,"Sin reporte",IF(E43=1,"Completada",IF(G43<46279,"Revisar retraso",IF(E43>0,"En curso","Sin iniciar")))) -> Sin reporte
...

Sheet Plan de trabajo
B2: PLAN DE TRABAJO
B4: Fechas y porcentaje se editan en el Gantt. Las predecesoras son una referencia y no restringen la programación.
B5: Horas activas: estimación editable. Los colores de los bloques y la marca de actividad crítica se cambian manualmente.
B7: Las fechas y los bloques son independientes: revisa ambos cuando reorganices una actividad.
B9: 54 actividades vinculadas a los ocho entregables del EDT.
B11: ID | C11: EDT | D11: Actividad | E11: Horas activas | F11: Predecesoras (referencia) | G11: Resultado verificable | H11: Inicio | I11: Fin | J11: Porcentaje
B12: M01 | C12: 1.1 | D12: Inventariar componentes, materiales y disponibilidad | E12: 6 | G12: Lista de materiales y faltantes confirmada. | H12: =IF(COUNT('Gantt 15 semanas'!F14)=0,"",'Gantt 15 semanas'!F14) -> 46258 | I12: =IF(COUNT('Gantt 15 semanas'!G14)=0,"",'Gantt 15 semanas'!G14) -> 46264 | J12: =IF(COUNT('Gantt 15 semanas'!E14)=0,"",'Gantt 15 semanas'!E14) -> 1
B13: M02 | C13: 1.1 | D13: Revisar STL, tolerancias y preparar el laminado | E13: 8 | F13: M01 | G13: Lotes de impresión y perfiles preparados. | H13: =IF(COUNT('Gantt 15 semanas'!F15)=0,"",'Gantt 15 semanas'!F15) -> 46265 | I13: =IF(COUNT('Gantt 15 semanas'!G15)=0,"",'Gantt 15 semanas'!G15) -> 46271 | J13: =IF(COUNT('Gantt 15 semanas'!E15)=0,"",'Gantt 15 semanas'!E15) -> 1
B14: M03 | C14: 1.1 | D14: Imprimir y verificar las piezas de la base | E14: 5 | F14: M02 | G14: Piezas completas, sin defectos funcionales. | H14: =IF(COUNT('Gantt 15 semanas'!F16)=0,"",'Gantt 15 semanas'!F16) -> 46272 | I14: =IF(COUNT('Gantt 15 semanas'!G16)=0,"",'Gantt 15 semanas'!G16) -> 46285 | J14: =IF(COUNT('Gantt 15 semanas'!E16)=0,"",'Gantt 15 semanas'!E16) -> 1
B15: M04 | C15: 1.1 | D15: Ensamblar chasis, ruedas y transmisión | E15: 10 | F15: M03 | G15: Base con movimiento mecánico libre. | H15: =IF(COUNT('Gantt 15 semanas'!F18)=0,"",'Gantt 15 semanas'!F18) -> 46286 | I15: =IF(COUNT('Gantt 15 semanas'!G18)=0,"",'Gantt 15 semanas'!G18) -> 46299 | J15: =IF(COUNT('Gantt 15 semanas'!E18)=0,"",'Gantt 15 semanas'!E18)
B16: M05 | C16: 1.2 | D16: Imprimir brazos, pinzas y estructura de elevación | E16: 7 | F16: M03 | G16: Lote estructural de brazos y elevación verificado. | H16: =IF(COUNT(#REF!)=0,"",#REF!) | I16: =IF(COUNT(#REF!)=0,"",#REF!) | J16: =IF(COUNT(#REF!)=0,"",#REF!)
B17: M06 | C17: 1.2 | D17: Ensamblar ambos brazos y las pinzas | E17: 14 | F17: M05, M04 | G17: Brazos y pinzas montados y ajustados. | H17: =IF(COUNT('Gantt 15 semanas'!F19)=0,"",'Gantt 15 semanas'!F19) -> 46293 | I17: =IF(COUNT('Gantt 15 semanas'!G19)=0,"",'Gantt 15 semanas'!G19) -> 46306 | J17: =IF(COUNT('Gantt 15 semanas'!E19)=0,"",'Gantt 15 semanas'!E19)
B18: M07 | C18: 1.2 | D18: Ensamblar y ajustar el mecanismo de elevación | E18: 8 | F18: M06 | G18: Elevación alineada y recorrido verificado. | H18: =IF(COUNT('Gantt 15 semanas'!F20)=0,"",'Gantt 15 semanas'!F20) -> 46300 | I18: =IF(COUNT('Gantt 15 semanas'!G20)=0,"",'Gantt 15 semanas'!G20) -> 46306 | J18: =IF(COUNT('Gantt 15 semanas'!E20)=0,"",'Gantt 15 semanas'!E20)
B19: M08 | C19: 1.3 | D19: Adaptar soportes de sensores, batería y cómputo | E19: 6 | F19: M02 | G19: Soportes dimensionados para la ubicación superior. | H19: =IF(COUNT('Gantt 15 semanas'!F21)=0,"",'Gantt 15 semanas'!F21) -> 46300 | I19: =IF(COUNT('Gantt 15 semanas'!G21)=0,"",'Gantt 15 semanas'!G21) -> 46306 | J19: =IF(COUNT('Gantt 15 semanas'!E21)=0,"",'Gantt 15 semanas'!E21)
B20: M09 | C20: 1.3 | D20: Imprimir y montar soportes; sujetar el cableado | E20: 6 | F20: M05, M08 | G20: Sensores y componentes sujetos, sin interferencias. | H20: =IF(COUNT('Gantt 15 semanas'!F22)=0,"",'Gantt 15 semanas'!F22) -> 46300 | I20: =IF(COUNT('Gantt 15 semanas'!G22)=0,"",'Gantt 15 semanas'!G22) -> 46306 | J20: =IF(COUNT('Gantt 15 semanas'!E22)=0,"",'Gantt 15 semanas'!E22)
B21: E01 | C21: 2.1 | D21: Definir distribución eléctrica y protecciones | E21: 6 | F21: M02 | G21: Diagrama eléctrico y protecciones seleccionados. | H21: =IF(COUNT('Gantt 15 semanas'!F24)=0,"",'Gantt 15 semanas'!F24) -> 46265 | I21: =IF(COUNT('Gantt 15 semanas'!G24)=0,"",'Gantt 15 semanas'!G24) -> 46271 | J21: =IF(COUNT('Gantt 15 semanas'!E24)=0,"",'Gantt 15 semanas'!E24) -> 1
B22: E02 | C22: 2.1 | D22: Integrar batería, regulación y cableado de potencia | E22: 10 | F22: M07, E01, M09 | G22: Tensiones y consumo verificados. | H22: =IF(COUNT('Gantt 15 semanas'!F25)=0,"",'Gantt 15 semanas'!F25) -> 46293 | I22: =IF(COUNT('Gantt 15 semanas'!G25)=0,"",'Gantt 15 semanas'!G25) -> 46299 | J22: =IF(COUNT('Gantt 15 semanas'!E25)=0,"",'Gantt 15 semanas'!E25)
B23: E03 | C23: 2.2 | D23: Configurar motores, referencias y límites | E23: 8 | F23: E02 | G23: Ruedas, brazos, pinzas y elevación controlables. | H23: =IF(COUNT('Gantt 15 semanas'!F26)=0,"",'Gantt 15 semanas'!F26) -> 46300 | I23: =IF(COUNT('Gantt 15 semanas'!G26)=0,"",'Gantt 15 semanas'!G26) -> 46306 | J23: =IF(COUNT('Gantt 15 semanas'!E26)=0,"",'Gantt 15 semanas'!E26)
B24: E04 | C24: 2.2 | D24: Verificar parada y movimientos manuales | E24: 3 | F24: E03 | G24: Prueba de parada y límites superada. | H24: =IF(COUNT('Gantt 15 semanas'!F27)=0,"",'Gantt 15 semanas'!F27) -> 46300 | I24: =IF(COUNT('Gantt 15 semanas'!G27)=0,"",'Gantt 15 semanas'!G27) -> 46306 | J24: =IF(COUNT('Gantt 15 semanas'!E27)=0,"",'Gantt 15 semanas'!E27)
B25: E05 | C25: 2.3 | D25: Conectar LiDAR, cámaras, computador y red | E25: 6 | F25: E02, M09 | G25: Datos y comunicaciones estables. | H25: =IF(COUNT('Gantt 15 semanas'!F28)=0,"",'Gantt 15 semanas'!F28) -> 46300 | I25: =IF(COUNT('Gantt 15 semanas'!G28)=0,"",'Gantt 15 semanas'!G28) -> 46306 | J25: =IF(COUNT('Gantt 15 semanas'!E28)=0,"",'Gantt 15 semanas'!E28)
B26: E06 | C26: 2.3 | D26: Calibrar sensores y comprobar sincronización | E26: 4 | F26: E05, E03 | G26: Calibración geométrica y marcas de tiempo verificadas. | H26: =IF(COUNT('Gantt 15 semanas'!F29)=0,"",'Gantt 15 semanas'!F29) -> 46300 | I26: =IF(COUNT('Gantt 15 semanas'!G29)=0,"",'Gantt 15 semanas'!G29) -> 46306 | J26: =IF(COUNT('Gantt 15 semanas'!E29)=0,"",'Gantt 15 semanas'!E29)
B27: N01 | C27: 3.1 | D27: Preparar DimOS, entorno y controladores base | E27: 8 | F27: M02 | G27: Entorno reproducible y controladores disponibles. | H27: =IF(COUNT('Gantt 15 semanas'!F31)=0,"",'Gantt 15 semanas'!F31) -> 46265 | I27: =IF(COUNT('Gantt 15 semanas'!G31)=0,"",'Gantt 15 semanas'!G31) -> 46278 | J27: =IF(COUNT('Gantt 15 semanas'!E31)=0,"",'Gantt 15 semanas'!E31) -> 1
B28: N02 | C28: 3.1 | D28: Integrar odometría y navegación de la base | E28: 10 | F28: N01, E04, E06 | G28: Robot localizado y controlado desde navegación. | H28: =IF(COUNT(#REF!)=0,"",#REF!) | I28: =IF(COUNT(#REF!)=0,"",#REF!) | J28: =IF(COUNT(#REF!)=0,"",#REF!)
B29: N03 | C29: 3.1 | D29: Mapear la vivienda y validar relocalización | E29: 6 | F29: N02 | G29: Mapa persistente de las zonas accesibles. | H29: =IF(COUNT('Gantt 15 semanas'!F34)=0,"",'Gantt 15 semanas'!F34) -> 46307 | I29: =IF(COUNT('Gantt 15 semanas'!G34)=0,"",'Gantt 15 semanas'!G34) -> 46320 | J29: =IF(COUNT('Gantt 15 semanas'!E34)=0,"",'Gantt 15 semanas'!E34)
B30: N04 | C30: 3.2 | D30: Configurar habitaciones y destinos semánticos | E30: 6 | F30: N03 | G30: Navegación a destinos nombrados verificada. | H30: =IF(COUNT('Gantt 15 semanas'!F35)=0,"",'Gantt 15 semanas'!F35) -> 46314 | I30: =IF(COUNT('Gantt 15 semanas'!G35)=0,"",'Gantt 15 semanas'!G35) -> 46327 | J30: =IF(COUNT('Gantt 15 semanas'!E35)=0,"",'Gantt 15 semanas'!E35)
B31: N05 | C31: 3.3 | D31: Ajustar aproximación a recogida y entrega | E31: 6 | F31: N04 | G31: Posiciones alcanzables y repetibles. | H31: =IF(COUNT('Gantt 15 semanas'!F37)=0,"",'Gantt 15 semanas'!F37) -> 46328 | I31: =IF(COUNT('Gantt 15 semanas'!G37)=0,"",'Gantt 15 semanas'!G37) -> 46334 | J31: =IF(COUNT('Gantt 15 semanas'!E37)=0,"",'Gantt 15 semanas'!E37)
B32: P01 | C32: 4.1 | D32: Integrar reconocimiento y localización de objetos | E32: 8 | F32: E06, N01 | G32: Botella y segundo objeto localizados visualmente. | H32: =IF(COUNT('Gantt 15 semanas'!F40)=0,"",'Gantt 15 semanas'!F40) -> 46307 | I32: =IF(COUNT('Gantt 15 semanas'!G40)=0,"",'Gantt 15 semanas'!G40) -> 46313 | J32: =IF(COUNT('Gantt 15 semanas'!E40)=0,"",'Gantt 15 semanas'!E40)
B33: P02 | C33: 4.2 | D33: Configurar memoria persistente de objetos y lugares | E33: 8 | F33: P01, N03 | G33: Ubicaciones y últimas observaciones recuperables. | H33: =IF(COUNT('Gantt 15 semanas'!F42)=0,"",'Gantt 15 semanas'!F42) -> 46314 | I33: =IF(COUNT('Gantt 15 semanas'!G42)=0,"",'Gantt 15 semanas'!G42) -> 46327 | J33: =IF(COUNT('Gantt 15 semanas'!E42)=0,"",'Gantt 15 semanas'!E42)
B34: P03 | C34: 4.3 | D34: Probar consultas, confirmación visual y actualización | E34: 6 | F34: P02 | G34: Objetos desplazados actualizan su ubicación recordada. | H34: =IF(COUNT('Gantt 15 semanas'!F43)=0,"",'Gantt 15 semanas'!F43) -> 46321 | I34: =IF(COUNT('Gantt 15 semanas'!G43)=0,"",'Gantt 15 semanas'!G43) -> 46334 | J34: =IF(COUNT('Gantt 15 semanas'!E43)=0,"",'Gantt 15 semanas'!E43)
B35: V01 | C35: 5.1 | D35: Definir instrucciones, etapas y formato de planes | E35: 5 | F35: N01 | G35: Planes estructurados y tareas iniciales delimitadas. | H35: =IF(COUNT('Gantt 15 semanas'!F45)=0,"",'Gantt 15 semanas'!F45) -> 46272 | I35: =IF(COUNT('Gantt 15 semanas'!G45)=0,"",'Gantt 15 semanas'!G45) -> 46285 | J35: =IF(COUNT('Gantt 15 semanas'!E45)=0,"",'Gantt 15 semanas'!E45) -> 1
B36: V02 | C36: 5.1 | D36: Configurar el VLM y probar interpretación de solicitudes | E36: 8 | F36: V01 | G36: Solicitudes de prueba producen planes válidos. | H36: =IF(COUNT('Gantt 15 semanas'!F47)=0,"",'Gantt 15 semanas'!F47) -> 46286 | I36: =IF(COUNT('Gantt 15 semanas'!G47)=0,"",'Gantt 15 semanas'!G47) -> 46299 | J36: =IF(COUNT('Gantt 15 semanas'!E47)=0,"",'Gantt 15 semanas'!E47)
B37: V03 | C37: 5.1 | D37: Conectar herramientas visuales y consulta de memoria | E37: 8 | F37: V02, P03 | G37: Planificador consulta observaciones y ubicaciones. | H37: =IF(COUNT('Gantt 15 semanas'!F48)=0,"",'Gantt 15 semanas'!F48) -> 46293 | I37: =IF(COUNT('Gantt 15 semanas'!G48)=0,"",'Gantt 15 semanas'!G48) -> 46299 | J37: =IF(COUNT('Gantt 15 semanas'!E48)=0,"",'Gantt 15 semanas'!E48)
B38: V04 | C38: 5.2 | D38: Implementar contrato, registro y selección de skills | E38: 8 | F38: V01, N01 | G38: Registro común con requisitos, entradas y resultados. | H38: =IF(COUNT('Gantt 15 semanas'!F49)=0,"",'Gantt 15 semanas'!F49) -> 46293 | I38: =IF(COUNT('Gantt 15 semanas'!G49)=0,"",'Gantt 15 semanas'!G49) -> 46306 | J38: =IF(COUNT('Gantt 15 semanas'!E49)=0,"",'Gantt 15 semanas'!E49)
B39: V05 | C39: 5.3 | D39: Programar supervisor, aclaraciones y gestión de fallos | E39: 10 | F39: V03, V04 | G39: Seguimiento de etapas, consultas y fallos registrados. | H39: =IF(COUNT('Gantt 15 semanas'!F50)=0,"",'Gantt 15 semanas'!F50) -> 46300 | I39: =IF(COUNT('Gantt 15 semanas'!G50)=0,"",'Gantt 15 semanas'!G50) -> 46306 | J39: =IF(COUNT('Gantt 15 semanas'!E50)=0,"",'Gantt 15 semanas'!E50)
B40: A01 | C40: 6.1.1 | D40: Configurar teleoperación y captura sincronizada | E40: 8 | F40: E04, E06 | G40: Grabación de imágenes, estados y acciones operativa. | H40: =IF(COUNT('Gantt 15 semanas'!F54)=0,"",'Gantt 15 semanas'!F54) -> 46307 | I40: =IF(COUNT('Gantt 15 semanas'!G54)=0,"",'Gantt 15 semanas'!G54) -> 46313 | J40: =IF(COUNT('Gantt 15 semanas'!E54)=0,"",'Gantt 15 semanas'!E54)
B41: A02 | C41: 6.1.1 | D41: Recolectar demostraciones de las habilidades iniciales | E41: 14 | F41: A01 | G41: Demostraciones de recogida y colocación accesible. | H41: =IF(COUNT('Gantt 15 semanas'!F55)=0,"",'Gantt 15 semanas'!F55) -> 46307 | I41: =IF(COUNT('Gantt 15 semanas'!G55)=0,"",'Gantt 15 semanas'!G55) -> 46320 | J41: =IF(COUNT('Gantt 15 semanas'!E55)=0,"",'Gantt 15 semanas'!E55)
B42: A03 | C42: 6.1.2 | D42: Revisar episodios y organizar datasets | E42: 7 | F42: A02 | G42: Episodios válidos, versiones y particiones definidas. | H42: =IF(COUNT('Gantt 15 semanas'!F56)=0,"",'Gantt 15 semanas'!F56) -> 46314 | I42: =IF(COUNT('Gantt 15 semanas'!G56)=0,"",'Gantt 15 semanas'!G56) -> 46320 | J42: =IF(COUNT('Gantt 15 semanas'!E56)=0,"",'Gantt 15 semanas'!E56)
B43: A04 | C43: 6.2.1 | D43: Entrenar las primeras políticas ACT | E43: 5 | F43: A03 | G43: Configuraciones, modelos y curvas de entrenamiento. | H43: =IF(COUNT('Gantt 15 semanas'!F57)=0,"",'Gantt 15 semanas'!F57) -> 46321 | I43: =IF(COUNT('Gantt 15 semanas'!G57)=0,"",'Gantt 15 semanas'!G57) -> 46327 | J43: =IF(COUNT('Gantt 15 semanas'!E57)=0,"",'Gantt 15 semanas'!E57)
B44: A05 | C44: 6.2.2 | D44: Evaluar políticas en pruebas físicas iniciales | E44: 9 | F44: A04 | G44: Éxitos, fallos y condiciones de inicio registrados. | H44: =IF(COUNT('Gantt 15 semanas'!F58)=0,"",'Gantt 15 semanas'!F58) -> 46321 | I44: =IF(COUNT('Gantt 15 semanas'!G58)=0,"",'Gantt 15 semanas'!G58) -> 46327 | J44: =IF(COUNT('Gantt 15 semanas'!E58)=0,"",'Gantt 15 semanas'!E58)
B45: A06 | C45: 6.1.2 | D45: Completar datos de fallos y revisar el dataset | E45: 7 | F45: A05 | G45: Demostraciones adicionales revisadas y versionadas. | H45: =IF(COUNT('Gantt 15 semanas'!F59)=0,"",'Gantt 15 semanas'!F59) -> 46328 | I45: =IF(COUNT('Gantt 15 semanas'!G59)=0,"",'Gantt 15 semanas'!G59) -> 46334 | J45: =IF(COUNT('Gantt 15 semanas'!E59)=0,"",'Gantt 15 semanas'!E59)
...
